2025-03-02 23:38:51,189 - INFO - Démarrage de la vérification d'intégrité du bot...
2025-03-02 23:38:51,189 - INFO - Vérification des composants essentiels...
2025-03-02 23:38:52,681 - INFO - Vérification des fichiers de configuration...
2025-03-02 23:38:52,682 - INFO - Vérification des variables d'environnement...
2025-03-02 23:38:52,682 - INFO - Vérification des dépendances Python...
2025-03-02 23:38:52,682 - INFO - 
===== RÉSULTATS DE LA VÉRIFICATION D'INTÉGRITÉ =====
2025-03-02 23:38:52,682 - INFO - Statut global: ERROR
2025-03-02 23:38:52,682 - INFO - 
Composants:
--- Logging error ---
Traceback (most recent call last):
  File "C:\Users\randr\AppData\Local\Programs\Python\Python311\Lib\logging\__init__.py", line 1113, in emit
    stream.write(msg + self.terminator)
  File "C:\Users\randr\AppData\Local\Programs\Python\Python311\Lib\encodings\cp1252.py", line 19, in encode
    return codecs.charmap_encode(input,self.errors,encoding_table)[0]
           ^^^^^^^^^^^^^^^^^^^^^^^^^^^^^^^^^^^^^^^^^^^^^^^^^^^^^^^
UnicodeEncodeError: 'charmap' codec can't encode characters in position 33-34: character maps to <undefined>
Call stack:
  File "C:\pythonProject1\verify_bot_integrity.py", line 348, in <module>
    exit_code = asyncio.run(verify_bot_integrity())
  File "C:\Users\randr\AppData\Local\Programs\Python\Python311\Lib\asyncio\runners.py", line 190, in run
    return runner.run(main)
  File "C:\Users\randr\AppData\Local\Programs\Python\Python311\Lib\asyncio\runners.py", line 118, in run
    return self._loop.run_until_complete(task)
  File "C:\Users\randr\AppData\Local\Programs\Python\Python311\Lib\asyncio\base_events.py", line 640, in run_until_complete
    self.run_forever()
  File "C:\Users\randr\AppData\Local\Programs\Python\Python311\Lib\asyncio\windows_events.py", line 321, in run_forever
    super().run_forever()
  File "C:\Users\randr\AppData\Local\Programs\Python\Python311\Lib\asyncio\base_events.py", line 607, in run_forever
    self._run_once()
  File "C:\Users\randr\AppData\Local\Programs\Python\Python311\Lib\asyncio\base_events.py", line 1922, in _run_once
    handle._run()
  File "C:\Users\randr\AppData\Local\Programs\Python\Python311\Lib\asyncio\events.py", line 80, in _run
    self._context.run(self._callback, *self._args)
  File "C:\pythonProject1\verify_bot_integrity.py", line 300, in verify_bot_integrity
    logging.info(f"{status_icon} {component_name}: {component_result['status'].upper()}")
Message: '\u26a0\ufe0f BlockchainClient: WARNING'
Arguments: ()
2025-03-02 23:38:52,682 - INFO - \u26a0\ufe0f BlockchainClient: WARNING
2025-03-02 23:38:52,736 - INFO -    - Méthodes manquantes: execute_swap, approve_token
--- Logging error ---
Traceback (most recent call last):
  File "C:\Users\randr\AppData\Local\Programs\Python\Python311\Lib\logging\__init__.py", line 1113, in emit
    stream.write(msg + self.terminator)
  File "C:\Users\randr\AppData\Local\Programs\Python\Python311\Lib\encodings\cp1252.py", line 19, in encode
    return codecs.charmap_encode(input,self.errors,encoding_table)[0]
           ^^^^^^^^^^^^^^^^^^^^^^^^^^^^^^^^^^^^^^^^^^^^^^^^^^^^^^^
UnicodeEncodeError: 'charmap' codec can't encode characters in position 33-34: character maps to <undefined>
Call stack:
  File "C:\pythonProject1\verify_bot_integrity.py", line 348, in <module>
    exit_code = asyncio.run(verify_bot_integrity())
  File "C:\Users\randr\AppData\Local\Programs\Python\Python311\Lib\asyncio\runners.py", line 190, in run
    return runner.run(main)
  File "C:\Users\randr\AppData\Local\Programs\Python\Python311\Lib\asyncio\runners.py", line 118, in run
    return self._loop.run_until_complete(task)
  File "C:\Users\randr\AppData\Local\Programs\Python\Python311\Lib\asyncio\base_events.py", line 640, in run_until_complete
    self.run_forever()
  File "C:\Users\randr\AppData\Local\Programs\Python\Python311\Lib\asyncio\windows_events.py", line 321, in run_forever
    super().run_forever()
  File "C:\Users\randr\AppData\Local\Programs\Python\Python311\Lib\asyncio\base_events.py", line 607, in run_forever
    self._run_once()
  File "C:\Users\randr\AppData\Local\Programs\Python\Python311\Lib\asyncio\base_events.py", line 1922, in _run_once
    handle._run()
  File "C:\Users\randr\AppData\Local\Programs\Python\Python311\Lib\asyncio\events.py", line 80, in _run
    self._context.run(self._callback, *self._args)
  File "C:\pythonProject1\verify_bot_integrity.py", line 300, in verify_bot_integrity
    logging.info(f"{status_icon} {component_name}: {component_result['status'].upper()}")
Message: '\u26a0\ufe0f PriceFeed: WARNING'
Arguments: ()
2025-03-02 23:38:52,736 - INFO - \u26a0\ufe0f PriceFeed: WARNING
2025-03-02 23:38:52,737 - INFO -    - Méthodes manquantes: get_dex_price, fetch_price
--- Logging error ---
Traceback (most recent call last):
  File "C:\Users\randr\AppData\Local\Programs\Python\Python311\Lib\logging\__init__.py", line 1113, in emit
    stream.write(msg + self.terminator)
  File "C:\Users\randr\AppData\Local\Programs\Python\Python311\Lib\encodings\cp1252.py", line 19, in encode
    return codecs.charmap_encode(input,self.errors,encoding_table)[0]
           ^^^^^^^^^^^^^^^^^^^^^^^^^^^^^^^^^^^^^^^^^^^^^^^^^^^^^^^
UnicodeEncodeError: 'charmap' codec can't encode character '\u2705' in position 33: character maps to <undefined>
Call stack:
  File "C:\pythonProject1\verify_bot_integrity.py", line 348, in <module>
    exit_code = asyncio.run(verify_bot_integrity())
  File "C:\Users\randr\AppData\Local\Programs\Python\Python311\Lib\asyncio\runners.py", line 190, in run
    return runner.run(main)
  File "C:\Users\randr\AppData\Local\Programs\Python\Python311\Lib\asyncio\runners.py", line 118, in run
    return self._loop.run_until_complete(task)
  File "C:\Users\randr\AppData\Local\Programs\Python\Python311\Lib\asyncio\base_events.py", line 640, in run_until_complete
    self.run_forever()
  File "C:\Users\randr\AppData\Local\Programs\Python\Python311\Lib\asyncio\windows_events.py", line 321, in run_forever
    super().run_forever()
  File "C:\Users\randr\AppData\Local\Programs\Python\Python311\Lib\asyncio\base_events.py", line 607, in run_forever
    self._run_once()
  File "C:\Users\randr\AppData\Local\Programs\Python\Python311\Lib\asyncio\base_events.py", line 1922, in _run_once
    handle._run()
  File "C:\Users\randr\AppData\Local\Programs\Python\Python311\Lib\asyncio\events.py", line 80, in _run
    self._context.run(self._callback, *self._args)
  File "C:\pythonProject1\verify_bot_integrity.py", line 300, in verify_bot_integrity
    logging.info(f"{status_icon} {component_name}: {component_result['status'].upper()}")
Message: '\u2705 ArbitrageStrategy: OK'
Arguments: ()
2025-03-02 23:38:52,737 - INFO - \u2705 ArbitrageStrategy: OK
--- Logging error ---
Traceback (most recent call last):
  File "C:\Users\randr\AppData\Local\Programs\Python\Python311\Lib\logging\__init__.py", line 1113, in emit
    stream.write(msg + self.terminator)
  File "C:\Users\randr\AppData\Local\Programs\Python\Python311\Lib\encodings\cp1252.py", line 19, in encode
    return codecs.charmap_encode(input,self.errors,encoding_table)[0]
           ^^^^^^^^^^^^^^^^^^^^^^^^^^^^^^^^^^^^^^^^^^^^^^^^^^^^^^^
UnicodeEncodeError: 'charmap' codec can't encode characters in position 33-34: character maps to <undefined>
Call stack:
  File "C:\pythonProject1\verify_bot_integrity.py", line 348, in <module>
    exit_code = asyncio.run(verify_bot_integrity())
  File "C:\Users\randr\AppData\Local\Programs\Python\Python311\Lib\asyncio\runners.py", line 190, in run
    return runner.run(main)
  File "C:\Users\randr\AppData\Local\Programs\Python\Python311\Lib\asyncio\runners.py", line 118, in run
    return self._loop.run_until_complete(task)
  File "C:\Users\randr\AppData\Local\Programs\Python\Python311\Lib\asyncio\base_events.py", line 640, in run_until_complete
    self.run_forever()
  File "C:\Users\randr\AppData\Local\Programs\Python\Python311\Lib\asyncio\windows_events.py", line 321, in run_forever
    super().run_forever()
  File "C:\Users\randr\AppData\Local\Programs\Python\Python311\Lib\asyncio\base_events.py", line 607, in run_forever
    self._run_once()
  File "C:\Users\randr\AppData\Local\Programs\Python\Python311\Lib\asyncio\base_events.py", line 1922, in _run_once
    handle._run()
  File "C:\Users\randr\AppData\Local\Programs\Python\Python311\Lib\asyncio\events.py", line 80, in _run
    self._context.run(self._callback, *self._args)
  File "C:\pythonProject1\verify_bot_integrity.py", line 300, in verify_bot_integrity
    logging.info(f"{status_icon} {component_name}: {component_result['status'].upper()}")
Message: '\u26a0\ufe0f MEVStrategy: WARNING'
Arguments: ()
2025-03-02 23:38:52,738 - INFO - \u26a0\ufe0f MEVStrategy: WARNING
2025-03-02 23:38:52,738 - INFO -    - Méthodes manquantes: scan_mempool, analyze_transaction, execute_strategy
--- Logging error ---
Traceback (most recent call last):
  File "C:\Users\randr\AppData\Local\Programs\Python\Python311\Lib\logging\__init__.py", line 1113, in emit
    stream.write(msg + self.terminator)
  File "C:\Users\randr\AppData\Local\Programs\Python\Python311\Lib\encodings\cp1252.py", line 19, in encode
    return codecs.charmap_encode(input,self.errors,encoding_table)[0]
           ^^^^^^^^^^^^^^^^^^^^^^^^^^^^^^^^^^^^^^^^^^^^^^^^^^^^^^^
UnicodeEncodeError: 'charmap' codec can't encode character '\u274c' in position 33: character maps to <undefined>
Call stack:
  File "C:\pythonProject1\verify_bot_integrity.py", line 348, in <module>
    exit_code = asyncio.run(verify_bot_integrity())
  File "C:\Users\randr\AppData\Local\Programs\Python\Python311\Lib\asyncio\runners.py", line 190, in run
    return runner.run(main)
  File "C:\Users\randr\AppData\Local\Programs\Python\Python311\Lib\asyncio\runners.py", line 118, in run
    return self._loop.run_until_complete(task)
  File "C:\Users\randr\AppData\Local\Programs\Python\Python311\Lib\asyncio\base_events.py", line 640, in run_until_complete
    self.run_forever()
  File "C:\Users\randr\AppData\Local\Programs\Python\Python311\Lib\asyncio\windows_events.py", line 321, in run_forever
    super().run_forever()
  File "C:\Users\randr\AppData\Local\Programs\Python\Python311\Lib\asyncio\base_events.py", line 607, in run_forever
    self._run_once()
  File "C:\Users\randr\AppData\Local\Programs\Python\Python311\Lib\asyncio\base_events.py", line 1922, in _run_once
    handle._run()
  File "C:\Users\randr\AppData\Local\Programs\Python\Python311\Lib\asyncio\events.py", line 80, in _run
    self._context.run(self._callback, *self._args)
  File "C:\pythonProject1\verify_bot_integrity.py", line 300, in verify_bot_integrity
    logging.info(f"{status_icon} {component_name}: {component_result['status'].upper()}")
Message: '\u274c SnipingStrategy: ERROR'
Arguments: ()
2025-03-02 23:38:52,738 - INFO - \u274c SnipingStrategy: ERROR
2025-03-02 23:38:52,739 - INFO -    - Impossible d'importer le module gbpbot.strategies.sniping: cannot import name 'FixtureFunction' from 'typing' (C:\Users\randr\AppData\Local\Programs\Python\Python311\Lib\typing.py)
--- Logging error ---
Traceback (most recent call last):
  File "C:\Users\randr\AppData\Local\Programs\Python\Python311\Lib\logging\__init__.py", line 1113, in emit
    stream.write(msg + self.terminator)
  File "C:\Users\randr\AppData\Local\Programs\Python\Python311\Lib\encodings\cp1252.py", line 19, in encode
    return codecs.charmap_encode(input,self.errors,encoding_table)[0]
           ^^^^^^^^^^^^^^^^^^^^^^^^^^^^^^^^^^^^^^^^^^^^^^^^^^^^^^^
UnicodeEncodeError: 'charmap' codec can't encode character '\u2705' in position 33: character maps to <undefined>
Call stack:
  File "C:\pythonProject1\verify_bot_integrity.py", line 348, in <module>
    exit_code = asyncio.run(verify_bot_integrity())
  File "C:\Users\randr\AppData\Local\Programs\Python\Python311\Lib\asyncio\runners.py", line 190, in run
    return runner.run(main)
  File "C:\Users\randr\AppData\Local\Programs\Python\Python311\Lib\asyncio\runners.py", line 118, in run
    return self._loop.run_until_complete(task)
  File "C:\Users\randr\AppData\Local\Programs\Python\Python311\Lib\asyncio\base_events.py", line 640, in run_until_complete
    self.run_forever()
  File "C:\Users\randr\AppData\Local\Programs\Python\Python311\Lib\asyncio\windows_events.py", line 321, in run_forever
    super().run_forever()
  File "C:\Users\randr\AppData\Local\Programs\Python\Python311\Lib\asyncio\base_events.py", line 607, in run_forever
    self._run_once()
  File "C:\Users\randr\AppData\Local\Programs\Python\Python311\Lib\asyncio\base_events.py", line 1922, in _run_once
    handle._run()
  File "C:\Users\randr\AppData\Local\Programs\Python\Python311\Lib\asyncio\events.py", line 80, in _run
    self._context.run(self._callback, *self._args)
  File "C:\pythonProject1\verify_bot_integrity.py", line 300, in verify_bot_integrity
    logging.info(f"{status_icon} {component_name}: {component_result['status'].upper()}")
Message: '\u2705 VersionManager: OK'
Arguments: ()
2025-03-02 23:38:52,739 - INFO - \u2705 VersionManager: OK
2025-03-02 23:38:52,739 - INFO - 
Fichiers de configuration:
--- Logging error ---
Traceback (most recent call last):
  File "C:\Users\randr\AppData\Local\Programs\Python\Python311\Lib\logging\__init__.py", line 1113, in emit
    stream.write(msg + self.terminator)
  File "C:\Users\randr\AppData\Local\Programs\Python\Python311\Lib\encodings\cp1252.py", line 19, in encode
    return codecs.charmap_encode(input,self.errors,encoding_table)[0]
           ^^^^^^^^^^^^^^^^^^^^^^^^^^^^^^^^^^^^^^^^^^^^^^^^^^^^^^^
UnicodeEncodeError: 'charmap' codec can't encode character '\u2705' in position 33: character maps to <undefined>
Call stack:
  File "C:\pythonProject1\verify_bot_integrity.py", line 348, in <module>
    exit_code = asyncio.run(verify_bot_integrity())
  File "C:\Users\randr\AppData\Local\Programs\Python\Python311\Lib\asyncio\runners.py", line 190, in run
    return runner.run(main)
  File "C:\Users\randr\AppData\Local\Programs\Python\Python311\Lib\asyncio\runners.py", line 118, in run
    return self._loop.run_until_complete(task)
  File "C:\Users\randr\AppData\Local\Programs\Python\Python311\Lib\asyncio\base_events.py", line 640, in run_until_complete
    self.run_forever()
  File "C:\Users\randr\AppData\Local\Programs\Python\Python311\Lib\asyncio\windows_events.py", line 321, in run_forever
    super().run_forever()
  File "C:\Users\randr\AppData\Local\Programs\Python\Python311\Lib\asyncio\base_events.py", line 607, in run_forever
    self._run_once()
  File "C:\Users\randr\AppData\Local\Programs\Python\Python311\Lib\asyncio\base_events.py", line 1922, in _run_once
    handle._run()
  File "C:\Users\randr\AppData\Local\Programs\Python\Python311\Lib\asyncio\events.py", line 80, in _run
    self._context.run(self._callback, *self._args)
  File "C:\pythonProject1\verify_bot_integrity.py", line 307, in verify_bot_integrity
    logging.info(f"{status_icon} Statut: {results['config_files']['status'].upper()}")
Message: '\u2705 Statut: OK'
Arguments: ()
2025-03-02 23:38:52,739 - INFO - \u2705 Statut: OK
2025-03-02 23:38:52,740 - INFO - 
Variables d'environnement:
--- Logging error ---
Traceback (most recent call last):
  File "C:\Users\randr\AppData\Local\Programs\Python\Python311\Lib\logging\__init__.py", line 1113, in emit
    stream.write(msg + self.terminator)
  File "C:\Users\randr\AppData\Local\Programs\Python\Python311\Lib\encodings\cp1252.py", line 19, in encode
    return codecs.charmap_encode(input,self.errors,encoding_table)[0]
           ^^^^^^^^^^^^^^^^^^^^^^^^^^^^^^^^^^^^^^^^^^^^^^^^^^^^^^^
UnicodeEncodeError: 'charmap' codec can't encode character '\u2705' in position 33: character maps to <undefined>
Call stack:
  File "C:\pythonProject1\verify_bot_integrity.py", line 348, in <module>
    exit_code = asyncio.run(verify_bot_integrity())
  File "C:\Users\randr\AppData\Local\Programs\Python\Python311\Lib\asyncio\runners.py", line 190, in run
    return runner.run(main)
  File "C:\Users\randr\AppData\Local\Programs\Python\Python311\Lib\asyncio\runners.py", line 118, in run
    return self._loop.run_until_complete(task)
  File "C:\Users\randr\AppData\Local\Programs\Python\Python311\Lib\asyncio\base_events.py", line 640, in run_until_complete
    self.run_forever()
  File "C:\Users\randr\AppData\Local\Programs\Python\Python311\Lib\asyncio\windows_events.py", line 321, in run_forever
    super().run_forever()
  File "C:\Users\randr\AppData\Local\Programs\Python\Python311\Lib\asyncio\base_events.py", line 607, in run_forever
    self._run_once()
  File "C:\Users\randr\AppData\Local\Programs\Python\Python311\Lib\asyncio\base_events.py", line 1922, in _run_once
    handle._run()
  File "C:\Users\randr\AppData\Local\Programs\Python\Python311\Lib\asyncio\events.py", line 80, in _run
    self._context.run(self._callback, *self._args)
  File "C:\pythonProject1\verify_bot_integrity.py", line 316, in verify_bot_integrity
    logging.info(f"{status_icon} Statut: {results['environment']['status'].upper()}")
Message: '\u2705 Statut: OK'
Arguments: ()
2025-03-02 23:38:52,740 - INFO - \u2705 Statut: OK
2025-03-02 23:38:52,740 - INFO - 
Dépendances Python:
--- Logging error ---
Traceback (most recent call last):
  File "C:\Users\randr\AppData\Local\Programs\Python\Python311\Lib\logging\__init__.py", line 1113, in emit
    stream.write(msg + self.terminator)
  File "C:\Users\randr\AppData\Local\Programs\Python\Python311\Lib\encodings\cp1252.py", line 19, in encode
    return codecs.charmap_encode(input,self.errors,encoding_table)[0]
           ^^^^^^^^^^^^^^^^^^^^^^^^^^^^^^^^^^^^^^^^^^^^^^^^^^^^^^^
UnicodeEncodeError: 'charmap' codec can't encode character '\u274c' in position 33: character maps to <undefined>
Call stack:
  File "C:\pythonProject1\verify_bot_integrity.py", line 348, in <module>
    exit_code = asyncio.run(verify_bot_integrity())
  File "C:\Users\randr\AppData\Local\Programs\Python\Python311\Lib\asyncio\runners.py", line 190, in run
    return runner.run(main)
  File "C:\Users\randr\AppData\Local\Programs\Python\Python311\Lib\asyncio\runners.py", line 118, in run
    return self._loop.run_until_complete(task)
  File "C:\Users\randr\AppData\Local\Programs\Python\Python311\Lib\asyncio\base_events.py", line 640, in run_until_complete
    self.run_forever()
  File "C:\Users\randr\AppData\Local\Programs\Python\Python311\Lib\asyncio\windows_events.py", line 321, in run_forever
    super().run_forever()
  File "C:\Users\randr\AppData\Local\Programs\Python\Python311\Lib\asyncio\base_events.py", line 607, in run_forever
    self._run_once()
  File "C:\Users\randr\AppData\Local\Programs\Python\Python311\Lib\asyncio\base_events.py", line 1922, in _run_once
    handle._run()
  File "C:\Users\randr\AppData\Local\Programs\Python\Python311\Lib\asyncio\events.py", line 80, in _run
    self._context.run(self._callback, *self._args)
  File "C:\pythonProject1\verify_bot_integrity.py", line 325, in verify_bot_integrity
    logging.info(f"{status_icon} Statut: {results['dependencies']['status'].upper()}")
Message: '\u274c Statut: ERROR'
Arguments: ()
2025-03-02 23:38:52,740 - INFO - \u274c Statut: ERROR
2025-03-02 23:38:52,740 - INFO -    - Dépendances manquantes: python-dotenv
2025-03-02 23:38:52,741 - INFO - 
Résultats détaillés sauvegardés dans integrity_results.json
2025-03-02 23:38:52,741 - ERROR - La vérification d'intégrité a échoué. Veuillez corriger les erreurs avant de continuer.
